// Handling errors with try-catch blocks
try {
  const pi = 3.4;

  pi = 5; // TypeError
}
catch(err) {
  console.log('We got an error!');
}


for(let i = 5; i <= 10; i++) {
  console.log(i);
}